[2024-10-04T21:12:27.171+0000] {taskinstance.py:1956} INFO - Dependencies all met for dep_context=non-requeueable deps ti=<TaskInstance: test_mysql_connection.test_connection manual__2024-10-04T21:03:00.868396+00:00 [queued]>
[2024-10-04T21:12:27.182+0000] {taskinstance.py:1956} INFO - Dependencies all met for dep_context=requeueable deps ti=<TaskInstance: test_mysql_connection.test_connection manual__2024-10-04T21:03:00.868396+00:00 [queued]>
[2024-10-04T21:12:27.183+0000] {taskinstance.py:2170} INFO - Starting attempt 2 of 2
[2024-10-04T21:12:27.203+0000] {taskinstance.py:2191} INFO - Executing <Task(MySqlOperator): test_connection> on 2024-10-04 21:03:00.868396+00:00
[2024-10-04T21:12:27.212+0000] {standard_task_runner.py:60} INFO - Started process 631 to run task
[2024-10-04T21:12:27.217+0000] {standard_task_runner.py:87} INFO - Running: ['***', 'tasks', 'run', 'test_mysql_connection', 'test_connection', 'manual__2024-10-04T21:03:00.868396+00:00', '--job-id', '17', '--raw', '--subdir', 'DAGS_FOLDER/testmysql.py', '--cfg-path', '/tmp/tmpgdqvjnhw']
[2024-10-04T21:12:27.222+0000] {standard_task_runner.py:88} INFO - Job 17: Subtask test_connection
[2024-10-04T21:12:27.280+0000] {task_command.py:423} INFO - Running <TaskInstance: test_mysql_connection.test_connection manual__2024-10-04T21:03:00.868396+00:00 [running]> on host 284eee4692f6
[2024-10-04T21:12:27.355+0000] {taskinstance.py:2480} INFO - Exporting env vars: AIRFLOW_CTX_DAG_OWNER='***' AIRFLOW_CTX_DAG_ID='test_mysql_connection' AIRFLOW_CTX_TASK_ID='test_connection' AIRFLOW_CTX_EXECUTION_DATE='2024-10-04T21:03:00.868396+00:00' AIRFLOW_CTX_TRY_NUMBER='2' AIRFLOW_CTX_DAG_RUN_ID='manual__2024-10-04T21:03:00.868396+00:00'
[2024-10-04T21:12:27.357+0000] {sql.py:276} INFO - Executing: SELECT 1;
[2024-10-04T21:12:27.368+0000] {base.py:83} INFO - Using connection ID 'mysql_conn_id' for task execution.
[2024-10-04T21:12:27.379+0000] {base.py:83} INFO - Using connection ID 'mysql_conn_id' for task execution.
[2024-10-04T21:12:27.386+0000] {taskinstance.py:2698} ERROR - Task failed with exception
Traceback (most recent call last):
  File "/home/airflow/.local/lib/python3.8/site-packages/airflow/models/taskinstance.py", line 433, in _execute_task
    result = execute_callable(context=context, **execute_callable_kwargs)
  File "/home/airflow/.local/lib/python3.8/site-packages/airflow/providers/common/sql/operators/sql.py", line 282, in execute
    output = hook.run(
  File "/home/airflow/.local/lib/python3.8/site-packages/airflow/providers/common/sql/hooks/sql.py", line 391, in run
    with closing(self.get_conn()) as conn:
  File "/home/airflow/.local/lib/python3.8/site-packages/airflow/providers/mysql/hooks/mysql.py", line 195, in get_conn
    return MySQLdb.connect(**conn_config)
  File "/home/airflow/.local/lib/python3.8/site-packages/MySQLdb/__init__.py", line 121, in Connect
    return Connection(*args, **kwargs)
  File "/home/airflow/.local/lib/python3.8/site-packages/MySQLdb/connections.py", line 193, in __init__
    super().__init__(*args, **kwargs2)
MySQLdb.OperationalError: (2002, "Can't connect to local server through socket '/run/mysqld/mysqld.sock' (2)")
[2024-10-04T21:12:27.396+0000] {taskinstance.py:1138} INFO - Marking task as FAILED. dag_id=test_mysql_connection, task_id=test_connection, execution_date=20241004T210300, start_date=20241004T211227, end_date=20241004T211227
[2024-10-04T21:12:27.409+0000] {standard_task_runner.py:107} ERROR - Failed to execute job 17 for task test_connection ((2002, "Can't connect to local server through socket '/run/mysqld/mysqld.sock' (2)"); 631)
[2024-10-04T21:12:27.431+0000] {local_task_job_runner.py:234} INFO - Task exited with return code 1
[2024-10-04T21:12:27.454+0000] {taskinstance.py:3280} INFO - 0 downstream tasks scheduled from follow-on schedule check
