[2024-10-04T21:07:24.756+0000] {taskinstance.py:1956} INFO - Dependencies all met for dep_context=non-requeueable deps ti=<TaskInstance: test_mysql_connection.test_connection manual__2024-10-04T21:03:00.868396+00:00 [queued]>
[2024-10-04T21:07:24.766+0000] {taskinstance.py:1956} INFO - Dependencies all met for dep_context=requeueable deps ti=<TaskInstance: test_mysql_connection.test_connection manual__2024-10-04T21:03:00.868396+00:00 [queued]>
[2024-10-04T21:07:24.767+0000] {taskinstance.py:2170} INFO - Starting attempt 1 of 2
[2024-10-04T21:07:24.784+0000] {taskinstance.py:2191} INFO - Executing <Task(MySqlOperator): test_connection> on 2024-10-04 21:03:00.868396+00:00
[2024-10-04T21:07:24.793+0000] {standard_task_runner.py:60} INFO - Started process 552 to run task
[2024-10-04T21:07:24.802+0000] {standard_task_runner.py:87} INFO - Running: ['***', 'tasks', 'run', 'test_mysql_connection', 'test_connection', 'manual__2024-10-04T21:03:00.868396+00:00', '--job-id', '15', '--raw', '--subdir', 'DAGS_FOLDER/testmysql.py', '--cfg-path', '/tmp/tmpodao2dr4']
[2024-10-04T21:07:24.807+0000] {standard_task_runner.py:88} INFO - Job 15: Subtask test_connection
[2024-10-04T21:07:24.891+0000] {task_command.py:423} INFO - Running <TaskInstance: test_mysql_connection.test_connection manual__2024-10-04T21:03:00.868396+00:00 [running]> on host 284eee4692f6
[2024-10-04T21:07:24.996+0000] {taskinstance.py:2480} INFO - Exporting env vars: AIRFLOW_CTX_DAG_OWNER='***' AIRFLOW_CTX_DAG_ID='test_mysql_connection' AIRFLOW_CTX_TASK_ID='test_connection' AIRFLOW_CTX_EXECUTION_DATE='2024-10-04T21:03:00.868396+00:00' AIRFLOW_CTX_TRY_NUMBER='1' AIRFLOW_CTX_DAG_RUN_ID='manual__2024-10-04T21:03:00.868396+00:00'
[2024-10-04T21:07:25.000+0000] {sql.py:276} INFO - Executing: SELECT 1;
[2024-10-04T21:07:25.013+0000] {base.py:83} INFO - Using connection ID 'mysql_conn_id' for task execution.
[2024-10-04T21:07:25.031+0000] {base.py:83} INFO - Using connection ID 'mysql_conn_id' for task execution.
[2024-10-04T21:07:25.058+0000] {taskinstance.py:2698} ERROR - Task failed with exception
Traceback (most recent call last):
  File "/home/airflow/.local/lib/python3.8/site-packages/airflow/models/taskinstance.py", line 433, in _execute_task
    result = execute_callable(context=context, **execute_callable_kwargs)
  File "/home/airflow/.local/lib/python3.8/site-packages/airflow/providers/common/sql/operators/sql.py", line 282, in execute
    output = hook.run(
  File "/home/airflow/.local/lib/python3.8/site-packages/airflow/providers/common/sql/hooks/sql.py", line 391, in run
    with closing(self.get_conn()) as conn:
  File "/home/airflow/.local/lib/python3.8/site-packages/airflow/providers/mysql/hooks/mysql.py", line 195, in get_conn
    return MySQLdb.connect(**conn_config)
  File "/home/airflow/.local/lib/python3.8/site-packages/MySQLdb/__init__.py", line 121, in Connect
    return Connection(*args, **kwargs)
  File "/home/airflow/.local/lib/python3.8/site-packages/MySQLdb/connections.py", line 193, in __init__
    super().__init__(*args, **kwargs2)
MySQLdb.OperationalError: (2002, "Can't connect to local server through socket '/run/mysqld/mysqld.sock' (2)")
[2024-10-04T21:07:25.072+0000] {taskinstance.py:1138} INFO - Marking task as UP_FOR_RETRY. dag_id=test_mysql_connection, task_id=test_connection, execution_date=20241004T210300, start_date=20241004T210724, end_date=20241004T210725
[2024-10-04T21:07:25.086+0000] {standard_task_runner.py:107} ERROR - Failed to execute job 15 for task test_connection ((2002, "Can't connect to local server through socket '/run/mysqld/mysqld.sock' (2)"); 552)
[2024-10-04T21:07:25.134+0000] {local_task_job_runner.py:234} INFO - Task exited with return code 1
[2024-10-04T21:07:25.154+0000] {taskinstance.py:3280} INFO - 0 downstream tasks scheduled from follow-on schedule check
