[2024-10-04T22:36:33.366+0000] {taskinstance.py:1956} INFO - Dependencies all met for dep_context=non-requeueable deps ti=<TaskInstance: create_table_in_postgres.create_table_task manual__2024-10-04T22:30:14.831825+00:00 [queued]>
[2024-10-04T22:36:33.380+0000] {taskinstance.py:1956} INFO - Dependencies all met for dep_context=requeueable deps ti=<TaskInstance: create_table_in_postgres.create_table_task manual__2024-10-04T22:30:14.831825+00:00 [queued]>
[2024-10-04T22:36:33.381+0000] {taskinstance.py:2170} INFO - Starting attempt 2 of 2
[2024-10-04T22:36:33.399+0000] {taskinstance.py:2191} INFO - Executing <Task(PostgresOperator): create_table_task> on 2024-10-04 22:30:14.831825+00:00
[2024-10-04T22:36:33.409+0000] {standard_task_runner.py:60} INFO - Started process 77 to run task
[2024-10-04T22:36:33.414+0000] {standard_task_runner.py:87} INFO - Running: ['***', 'tasks', 'run', 'create_table_in_postgres', 'create_table_task', 'manual__2024-10-04T22:30:14.831825+00:00', '--job-id', '117', '--raw', '--subdir', 'DAGS_FOLDER/create_mysql_table.py', '--cfg-path', '/tmp/tmplq0ciid2']
[2024-10-04T22:36:33.447+0000] {standard_task_runner.py:88} INFO - Job 117: Subtask create_table_task
[2024-10-04T22:36:33.571+0000] {task_command.py:423} INFO - Running <TaskInstance: create_table_in_postgres.create_table_task manual__2024-10-04T22:30:14.831825+00:00 [running]> on host 77902c09fe27
[2024-10-04T22:36:33.756+0000] {taskinstance.py:2480} INFO - Exporting env vars: AIRFLOW_CTX_DAG_OWNER='***' AIRFLOW_CTX_DAG_ID='create_table_in_postgres' AIRFLOW_CTX_TASK_ID='create_table_task' AIRFLOW_CTX_EXECUTION_DATE='2024-10-04T22:30:14.831825+00:00' AIRFLOW_CTX_TRY_NUMBER='2' AIRFLOW_CTX_DAG_RUN_ID='manual__2024-10-04T22:30:14.831825+00:00'
[2024-10-04T22:36:33.760+0000] {sql.py:276} INFO - Executing: 
        CREATE TABLE IF NOT EXISTS clients (
            id SERIAL PRIMARY KEY,
            nom VARCHAR(100) NOT NULL,
            email VARCHAR(100) UNIQUE NOT NULL
        );
        
[2024-10-04T22:36:33.786+0000] {base.py:83} INFO - Using connection ID 'postgres_conn_id' for task execution.
[2024-10-04T22:36:33.809+0000] {base.py:83} INFO - Using connection ID 'postgres_conn_id' for task execution.
[2024-10-04T22:36:33.818+0000] {taskinstance.py:2698} ERROR - Task failed with exception
Traceback (most recent call last):
  File "/home/airflow/.local/lib/python3.8/site-packages/airflow/models/taskinstance.py", line 433, in _execute_task
    result = execute_callable(context=context, **execute_callable_kwargs)
  File "/home/airflow/.local/lib/python3.8/site-packages/airflow/providers/common/sql/operators/sql.py", line 282, in execute
    output = hook.run(
  File "/home/airflow/.local/lib/python3.8/site-packages/airflow/providers/common/sql/hooks/sql.py", line 391, in run
    with closing(self.get_conn()) as conn:
  File "/home/airflow/.local/lib/python3.8/site-packages/airflow/providers/postgres/hooks/postgres.py", line 158, in get_conn
    self.conn = psycopg2.connect(**conn_args)
  File "/home/airflow/.local/lib/python3.8/site-packages/psycopg2/__init__.py", line 122, in connect
    conn = _connect(dsn, connection_factory=connection_factory, **kwasync)
psycopg2.OperationalError: connection to server at "localhost" (::1), port 5432 failed: Connection refused
	Is the server running on that host and accepting TCP/IP connections?
connection to server at "localhost" (127.0.0.1), port 5432 failed: Connection refused
	Is the server running on that host and accepting TCP/IP connections?

[2024-10-04T22:36:33.831+0000] {taskinstance.py:1138} INFO - Marking task as FAILED. dag_id=create_table_in_postgres, task_id=create_table_task, execution_date=20241004T223014, start_date=20241004T223633, end_date=20241004T223633
[2024-10-04T22:36:33.851+0000] {standard_task_runner.py:107} ERROR - Failed to execute job 117 for task create_table_task (connection to server at "localhost" (::1), port 5432 failed: Connection refused
	Is the server running on that host and accepting TCP/IP connections?
connection to server at "localhost" (127.0.0.1), port 5432 failed: Connection refused
	Is the server running on that host and accepting TCP/IP connections?
; 77)
[2024-10-04T22:36:33.867+0000] {local_task_job_runner.py:234} INFO - Task exited with return code 1
[2024-10-04T22:36:33.886+0000] {taskinstance.py:3280} INFO - 0 downstream tasks scheduled from follow-on schedule check
