[2024-10-04T21:28:48.057+0000] {scheduler_job_runner.py:781} ERROR - Executor reports task instance <TaskInstance: create_mysql_table.create_table manual__2024-10-04T21:28:44.402603+00:00 [queued]> finished (failed) although the task says it's queued. (Info: None) Was the task killed externally?
