[2024-10-08T00:58:49.849+0000] {taskinstance.py:1956} INFO - Dependencies all met for dep_context=non-requeueable deps ti=<TaskInstance: data_processing_dag.process_data manual__2024-10-08T00:58:39.285105+00:00 [queued]>
[2024-10-08T00:58:49.885+0000] {taskinstance.py:1956} INFO - Dependencies all met for dep_context=requeueable deps ti=<TaskInstance: data_processing_dag.process_data manual__2024-10-08T00:58:39.285105+00:00 [queued]>
[2024-10-08T00:58:49.886+0000] {taskinstance.py:2170} INFO - Starting attempt 1 of 2
[2024-10-08T00:58:49.924+0000] {taskinstance.py:2191} INFO - Executing <Task(PythonOperator): process_data> on 2024-10-08 00:58:39.285105+00:00
[2024-10-08T00:58:50.121+0000] {standard_task_runner.py:60} INFO - Started process 100 to run task
[2024-10-08T00:58:50.142+0000] {standard_task_runner.py:87} INFO - Running: ['***', 'tasks', 'run', 'data_processing_dag', 'process_data', 'manual__2024-10-08T00:58:39.285105+00:00', '--job-id', '202', '--raw', '--subdir', 'DAGS_FOLDER/testpython.py', '--cfg-path', '/tmp/tmpdtd_o5ot']
[2024-10-08T00:58:50.145+0000] {standard_task_runner.py:88} INFO - Job 202: Subtask process_data
[2024-10-08T00:58:50.328+0000] {task_command.py:423} INFO - Running <TaskInstance: data_processing_dag.process_data manual__2024-10-08T00:58:39.285105+00:00 [running]> on host ffa59a91c4ec
[2024-10-08T00:58:51.004+0000] {taskinstance.py:2480} INFO - Exporting env vars: AIRFLOW_CTX_DAG_OWNER='***' AIRFLOW_CTX_DAG_ID='data_processing_dag' AIRFLOW_CTX_TASK_ID='process_data' AIRFLOW_CTX_EXECUTION_DATE='2024-10-08T00:58:39.285105+00:00' AIRFLOW_CTX_TRY_NUMBER='1' AIRFLOW_CTX_DAG_RUN_ID='manual__2024-10-08T00:58:39.285105+00:00'
[2024-10-08T00:58:51.036+0000] {taskinstance.py:2698} ERROR - Task failed with exception
Traceback (most recent call last):
  File "/home/airflow/.local/lib/python3.8/site-packages/airflow/models/taskinstance.py", line 433, in _execute_task
    result = execute_callable(context=context, **execute_callable_kwargs)
  File "/home/airflow/.local/lib/python3.8/site-packages/airflow/operators/python.py", line 199, in execute
    return_value = self.execute_callable()
  File "/home/airflow/.local/lib/python3.8/site-packages/airflow/operators/python.py", line 216, in execute_callable
    return self.python_callable(*self.op_args, **self.op_kwargs)
  File "/opt/airflow/dags/testpython.py", line 12, in process_data
    df = pd.read_csv(file_path, sep=';')
  File "/home/airflow/.local/lib/python3.8/site-packages/pandas/io/parsers/readers.py", line 912, in read_csv
    return _read(filepath_or_buffer, kwds)
  File "/home/airflow/.local/lib/python3.8/site-packages/pandas/io/parsers/readers.py", line 577, in _read
    parser = TextFileReader(filepath_or_buffer, **kwds)
  File "/home/airflow/.local/lib/python3.8/site-packages/pandas/io/parsers/readers.py", line 1407, in __init__
    self._engine = self._make_engine(f, self.engine)
  File "/home/airflow/.local/lib/python3.8/site-packages/pandas/io/parsers/readers.py", line 1661, in _make_engine
    self.handles = get_handle(
  File "/home/airflow/.local/lib/python3.8/site-packages/pandas/io/common.py", line 859, in get_handle
    handle = open(
FileNotFoundError: [Errno 2] No such file or directory: 'C:\\Users\\hamza\\OneDrive\\Documents\\testpython.csv'
[2024-10-08T00:58:51.094+0000] {taskinstance.py:1138} INFO - Marking task as UP_FOR_RETRY. dag_id=data_processing_dag, task_id=process_data, execution_date=20241008T005839, start_date=20241008T005849, end_date=20241008T005851
[2024-10-08T00:58:51.151+0000] {standard_task_runner.py:107} ERROR - Failed to execute job 202 for task process_data ([Errno 2] No such file or directory: 'C:\\Users\\hamza\\OneDrive\\Documents\\testpython.csv'; 100)
[2024-10-08T00:58:51.246+0000] {local_task_job_runner.py:234} INFO - Task exited with return code 1
[2024-10-08T00:58:51.584+0000] {taskinstance.py:3280} INFO - 0 downstream tasks scheduled from follow-on schedule check
