[2024-10-04T20:58:53.374+0000] {taskinstance.py:1956} INFO - Dependencies all met for dep_context=non-requeueable deps ti=<TaskInstance: create_mysql_table.create_table manual__2024-10-04T20:53:08.061350+00:00 [queued]>
[2024-10-04T20:58:53.388+0000] {taskinstance.py:1956} INFO - Dependencies all met for dep_context=requeueable deps ti=<TaskInstance: create_mysql_table.create_table manual__2024-10-04T20:53:08.061350+00:00 [queued]>
[2024-10-04T20:58:53.388+0000] {taskinstance.py:2170} INFO - Starting attempt 2 of 2
[2024-10-04T20:58:53.416+0000] {taskinstance.py:2191} INFO - Executing <Task(MySqlOperator): create_table> on 2024-10-04 20:53:08.061350+00:00
[2024-10-04T20:58:53.428+0000] {standard_task_runner.py:60} INFO - Started process 403 to run task
[2024-10-04T20:58:53.432+0000] {standard_task_runner.py:87} INFO - Running: ['***', 'tasks', 'run', 'create_mysql_table', 'create_table', 'manual__2024-10-04T20:53:08.061350+00:00', '--job-id', '6', '--raw', '--subdir', 'DAGS_FOLDER/testmysql.py', '--cfg-path', '/tmp/tmpacc7d1te']
[2024-10-04T20:58:53.436+0000] {standard_task_runner.py:88} INFO - Job 6: Subtask create_table
[2024-10-04T20:58:53.504+0000] {task_command.py:423} INFO - Running <TaskInstance: create_mysql_table.create_table manual__2024-10-04T20:53:08.061350+00:00 [running]> on host 284eee4692f6
[2024-10-04T20:58:53.596+0000] {taskinstance.py:2480} INFO - Exporting env vars: AIRFLOW_CTX_DAG_OWNER='***' AIRFLOW_CTX_DAG_ID='create_mysql_table' AIRFLOW_CTX_TASK_ID='create_table' AIRFLOW_CTX_EXECUTION_DATE='2024-10-04T20:53:08.061350+00:00' AIRFLOW_CTX_TRY_NUMBER='2' AIRFLOW_CTX_DAG_RUN_ID='manual__2024-10-04T20:53:08.061350+00:00'
[2024-10-04T20:58:53.598+0000] {sql.py:276} INFO - Executing: 
    CREATE TABLE IF NOT EXISTS my_table (
        id INT AUTO_INCREMENT PRIMARY KEY,
        name VARCHAR(255) NOT NULL,
        age INT NOT NULL
    );
    
[2024-10-04T20:58:53.613+0000] {base.py:83} INFO - Using connection ID 'mysql_conn_id' for task execution.
[2024-10-04T20:58:53.627+0000] {base.py:83} INFO - Using connection ID 'mysql_conn_id' for task execution.
[2024-10-04T20:58:53.641+0000] {taskinstance.py:2698} ERROR - Task failed with exception
Traceback (most recent call last):
  File "/home/airflow/.local/lib/python3.8/site-packages/airflow/models/taskinstance.py", line 433, in _execute_task
    result = execute_callable(context=context, **execute_callable_kwargs)
  File "/home/airflow/.local/lib/python3.8/site-packages/airflow/providers/common/sql/operators/sql.py", line 282, in execute
    output = hook.run(
  File "/home/airflow/.local/lib/python3.8/site-packages/airflow/providers/common/sql/hooks/sql.py", line 391, in run
    with closing(self.get_conn()) as conn:
  File "/home/airflow/.local/lib/python3.8/site-packages/airflow/providers/mysql/hooks/mysql.py", line 195, in get_conn
    return MySQLdb.connect(**conn_config)
  File "/home/airflow/.local/lib/python3.8/site-packages/MySQLdb/__init__.py", line 121, in Connect
    return Connection(*args, **kwargs)
  File "/home/airflow/.local/lib/python3.8/site-packages/MySQLdb/connections.py", line 193, in __init__
    super().__init__(*args, **kwargs2)
MySQLdb.OperationalError: (2002, "Can't connect to local server through socket '/run/mysqld/mysqld.sock' (2)")
[2024-10-04T20:58:53.654+0000] {taskinstance.py:1138} INFO - Marking task as FAILED. dag_id=create_mysql_table, task_id=create_table, execution_date=20241004T205308, start_date=20241004T205853, end_date=20241004T205853
[2024-10-04T20:58:53.672+0000] {standard_task_runner.py:107} ERROR - Failed to execute job 6 for task create_table ((2002, "Can't connect to local server through socket '/run/mysqld/mysqld.sock' (2)"); 403)
[2024-10-04T20:58:53.727+0000] {local_task_job_runner.py:234} INFO - Task exited with return code 1
[2024-10-04T20:58:53.757+0000] {taskinstance.py:3280} INFO - 0 downstream tasks scheduled from follow-on schedule check
