[2024-10-04T21:56:58.843+0000] {taskinstance.py:1956} INFO - Dependencies all met for dep_context=non-requeueable deps ti=<TaskInstance: create_table_in_mysql.create_table_task scheduled__2023-10-04T00:00:00+00:00 [queued]>
[2024-10-04T21:56:58.865+0000] {taskinstance.py:1956} INFO - Dependencies all met for dep_context=requeueable deps ti=<TaskInstance: create_table_in_mysql.create_table_task scheduled__2023-10-04T00:00:00+00:00 [queued]>
[2024-10-04T21:56:58.867+0000] {taskinstance.py:2170} INFO - Starting attempt 1 of 2
[2024-10-04T21:56:58.909+0000] {taskinstance.py:2191} INFO - Executing <Task(MySqlOperator): create_table_task> on 2023-10-04 00:00:00+00:00
[2024-10-04T21:56:58.930+0000] {standard_task_runner.py:60} INFO - Started process 276 to run task
[2024-10-04T21:56:58.936+0000] {standard_task_runner.py:87} INFO - Running: ['***', 'tasks', 'run', 'create_table_in_mysql', 'create_table_task', 'scheduled__2023-10-04T00:00:00+00:00', '--job-id', '37', '--raw', '--subdir', 'DAGS_FOLDER/create_mysql_table.py', '--cfg-path', '/tmp/tmpw2hi0yng']
[2024-10-04T21:56:58.941+0000] {standard_task_runner.py:88} INFO - Job 37: Subtask create_table_task
[2024-10-04T21:57:00.457+0000] {task_command.py:423} INFO - Running <TaskInstance: create_table_in_mysql.create_table_task scheduled__2023-10-04T00:00:00+00:00 [running]> on host e8b05ac5a569
[2024-10-04T21:57:00.623+0000] {taskinstance.py:2480} INFO - Exporting env vars: AIRFLOW_CTX_DAG_OWNER='***' AIRFLOW_CTX_DAG_ID='create_table_in_mysql' AIRFLOW_CTX_TASK_ID='create_table_task' AIRFLOW_CTX_EXECUTION_DATE='2023-10-04T00:00:00+00:00' AIRFLOW_CTX_TRY_NUMBER='1' AIRFLOW_CTX_DAG_RUN_ID='scheduled__2023-10-04T00:00:00+00:00'
[2024-10-04T21:57:00.632+0000] {sql.py:276} INFO - Executing: 
        CREATE TABLE IF NOT EXISTS clients (
            id INT AUTO_INCREMENT PRIMARY KEY,
            nom VARCHAR(100) NOT NULL,
            email VARCHAR(100) UNIQUE NOT NULL
        );
        
[2024-10-04T21:57:00.652+0000] {base.py:83} INFO - Using connection ID 'mysql_conn_id' for task execution.
[2024-10-04T21:57:00.676+0000] {base.py:83} INFO - Using connection ID 'mysql_conn_id' for task execution.
[2024-10-04T21:57:00.688+0000] {taskinstance.py:2698} ERROR - Task failed with exception
Traceback (most recent call last):
  File "/home/airflow/.local/lib/python3.8/site-packages/airflow/models/taskinstance.py", line 433, in _execute_task
    result = execute_callable(context=context, **execute_callable_kwargs)
  File "/home/airflow/.local/lib/python3.8/site-packages/airflow/providers/common/sql/operators/sql.py", line 282, in execute
    output = hook.run(
  File "/home/airflow/.local/lib/python3.8/site-packages/airflow/providers/common/sql/hooks/sql.py", line 391, in run
    with closing(self.get_conn()) as conn:
  File "/home/airflow/.local/lib/python3.8/site-packages/airflow/providers/mysql/hooks/mysql.py", line 195, in get_conn
    return MySQLdb.connect(**conn_config)
  File "/home/airflow/.local/lib/python3.8/site-packages/MySQLdb/__init__.py", line 121, in Connect
    return Connection(*args, **kwargs)
  File "/home/airflow/.local/lib/python3.8/site-packages/MySQLdb/connections.py", line 193, in __init__
    super().__init__(*args, **kwargs2)
MySQLdb.OperationalError: (2002, "Can't connect to local server through socket '/run/mysqld/mysqld.sock' (2)")
[2024-10-04T21:57:00.703+0000] {taskinstance.py:1138} INFO - Marking task as UP_FOR_RETRY. dag_id=create_table_in_mysql, task_id=create_table_task, execution_date=20231004T000000, start_date=20241004T215658, end_date=20241004T215700
[2024-10-04T21:57:00.726+0000] {standard_task_runner.py:107} ERROR - Failed to execute job 37 for task create_table_task ((2002, "Can't connect to local server through socket '/run/mysqld/mysqld.sock' (2)"); 276)
[2024-10-04T21:57:00.762+0000] {local_task_job_runner.py:234} INFO - Task exited with return code 1
[2024-10-04T21:57:00.804+0000] {taskinstance.py:3280} INFO - 0 downstream tasks scheduled from follow-on schedule check
