[2024-10-04T23:23:37.028+0000] {scheduler_job_runner.py:781} ERROR - Executor reports task instance <TaskInstance: create_table_in_mysql.create_table_task manual__2024-10-04T23:23:29.885832+00:00 [queued]> finished (failed) although the task says it's queued. (Info: None) Was the task killed externally?
